File: Experiment/4_CrystalGrowth/BaTio3.csv
[Measurement conditions]
Sample identification,
Comment - 1,"Configuration=Flat sample stage, Owner=User-1, Creation date=9/4/2017 1:38:11 PM"
Comment - 2,"Goniometer=PW3050/60 (Theta/Theta); Minimum step size 2Theta:0.001; Minimum step size Omega:0.001"
Comment - 3,"Sample stage=PW3071/xx Bracket"
Comment - 4,"Diffractometer system=XPERT-PRO"
Comment - 5,"Measurement program=C:\PANalytical\Data Collector\Programs\KTH_FSS.xrdmp, Identifier={66F37155-83A8-48B8-A400-FEDCA643D064}"
Anode material,Cu
K-Alpha1 wavelength,1.5405980
K-Alpha2 wavelength,1.5444260
Ratio K-Alpha2/K-Alpha1,0.500
Divergence slit,Fixed,0.38mm
Monochromator used,NO
Generator voltage, 40
Tube current, 30
File date and time,03/Jul/2020 12:16
Unit cell,
h k l, 0 0 0
Scan axis,Gonio
Scan range,10.009999997,89.999681013
Scan step size,0.0262606
No. of points, 3046
Scan type,CONTINUOUS
Time per step,126.990
[Scan points]
Angle,Intensity
10.023130280,1362.0
10.101911975,1329.0
10.180693670,1320.0
10.259475365,1304.0
10.338257060,1322.0
10.417038755,1285.0
10.495820450,1246.0
10.574602145,1249.0
10.653383840,1286.0
10.732165535,1273.0
10.810947230,1251.0
10.889728925,1254.0
10.968510620,1232.0
11.047292315,1267.0
11.126074010,1229.0
11.204855705,1280.0
11.283637400,1234.0
11.362419095,1234.0
11.441200790,1136.0
11.519982485,1260.0
11.598764180,1193.0
11.677545876,1239.0
11.756327571,1249.0
11.835109266,1195.0
11.913890961,1292.0
11.992672656,1199.0
12.071454351,1138.0
12.150236046,1143.0
12.229017741,1142.0
12.307799436,1195.0
12.386581131,1136.0
12.465362826,1218.0
12.544144521,1149.0
12.622926216,1201.0
12.701707911,1171.0
12.780489606,1187.0
12.859271301,1118.0
12.938052996,1072.0
13.016834691,1190.0
13.095616386,1122.0
13.174398081,1074.0
13.253179776,1220.0
13.331961471,1094.0
13.410743166,1093.0
13.489524861,1083.0
13.568306556,1087.0
13.647088251,1072.0
13.725869946,1016.0
13.804651641,1021.0
13.883433336,1034.0
13.962215031,1057.0
14.040996726,1029.0
14.119778421,1101.0
14.198560116,1036.0
14.277341811,1041.0
14.356123506,993.0
14.434905201,965.0
14.513686896,929.0
14.592468591,999.0
14.671250286,1021.0
14.750031981,974.0
14.828813677,992.0
14.907595372,1003.0
14.986377067,978.0
15.065158762,1000.0
15.143940457,995.0
15.222722152,951.0
15.301503847,993.0
15.380285542,956.0
15.459067237,994.0
15.537848932,977.0
15.616630627,981.0
15.695412322,899.0
15.774194017,909.0
15.852975712,910.0
15.931757407,909.0
16.010539102,937.0
16.089320797,950.0
16.168102492,910.0
16.246884187,852.0
16.325665882,892.0
16.404447577,920.0
16.483229272,931.0
16.562010967,879.0
16.640792662,839.0
16.719574357,860.0
16.798356052,852.0
16.877137747,868.0
16.955919442,841.0
17.034701137,878.0
17.113482832,885.0
17.192264527,839.0
17.271046222,855.0
17.349827917,803.0
17.428609612,794.0
17.507391307,918.0
17.586173002,877.0
17.664954697,820.0
17.743736392,861.0
17.822518087,800.0
17.901299782,843.0
17.980081477,833.0
18.058863173,753.0
18.137644868,848.0
18.216426563,769.0
18.295208258,844.0
18.373989953,768.0
18.452771648,791.0
18.531553343,791.0
18.610335038,814.0
18.689116733,711.0
18.767898428,755.0
18.846680123,759.0
18.925461818,844.0
19.004243513,721.0
19.083025208,778.0
19.161806903,808.0
19.240588598,743.0
19.319370293,740.0
19.398151988,774.0
19.476933683,710.0
19.555715378,744.0
19.634497073,676.0
19.713278768,731.0
19.792060463,737.0
19.870842158,731.0
19.949623853,718.0
20.028405548,726.0
20.107187243,663.0
20.185968938,721.0
20.264750633,734.0
20.343532328,752.0
20.422314023,688.0
20.501095718,703.0
20.579877413,723.0
20.658659108,683.0
20.737440803,686.0
20.816222498,677.0
20.895004193,676.0
20.973785888,670.0
21.052567583,670.0
21.131349278,659.0
21.210130973,616.0
21.288912669,644.0
21.367694364,704.0
21.446476059,634.0
21.525257754,673.0
21.604039449,725.0
21.682821144,682.0
21.761602839,698.0
21.840384534,776.0
21.919166229,972.0
21.997947924,1273.0
22.076729619,2162.0
22.155511314,2848.0
22.234293009,3154.0
22.313074704,3300.0
22.391856399,1562.0
22.470638094,882.0
22.549419789,699.0
22.628201484,693.0
22.706983179,679.0
22.785764874,621.0
22.864546569,606.0
22.943328264,632.0
23.022109959,609.0
23.100891654,627.0
23.179673349,552.0
23.258455044,569.0
23.337236739,577.0
23.416018434,534.0
23.494800129,522.0
23.573581824,611.0
23.652363519,594.0
23.731145214,588.0
23.809926909,632.0
23.888708604,639.0
23.967490299,730.0
24.046271994,752.0
24.125053689,670.0
24.203835384,667.0
24.282617079,619.0
24.361398774,569.0
24.440180470,559.0
24.518962165,557.0
24.597743860,558.0
24.676525555,540.0
24.755307250,527.0
24.834088945,546.0
24.912870640,490.0
24.991652335,548.0
25.070434030,554.0
25.149215725,545.0
25.227997420,525.0
25.306779115,508.0
25.385560810,533.0
25.464342505,502.0
25.543124200,549.0
25.621905895,499.0
25.700687590,529.0
25.779469285,481.0
25.858250980,515.0
25.937032675,523.0
26.015814370,470.0
26.094596065,499.0
26.173377760,506.0
26.252159455,481.0
26.330941150,478.0
26.409722845,517.0
26.488504540,507.0
26.567286235,499.0
26.646067930,490.0
26.724849625,466.0
26.803631320,469.0
26.882413015,471.0
26.961194710,493.0
27.039976405,471.0
27.118758100,444.0
27.197539795,447.0
27.276321490,445.0
27.355103185,472.0
27.433884880,476.0
27.512666575,481.0
27.591448270,452.0
27.670229966,482.0
27.749011661,483.0
27.827793356,489.0
27.906575051,482.0
27.985356746,485.0
28.064138441,449.0
28.142920136,453.0
28.221701831,489.0
28.300483526,463.0
28.379265221,452.0
28.458046916,500.0
28.536828611,470.0
28.615610306,461.0
28.694392001,451.0
28.773173696,480.0
28.851955391,479.0
28.930737086,448.0
29.009518781,464.0
29.088300476,466.0
29.167082171,425.0
29.245863866,467.0
29.324645561,451.0
29.403427256,436.0
29.482208951,432.0
29.560990646,442.0
29.639772341,434.0
29.718554036,432.0
29.797335731,481.0
29.876117426,425.0
29.954899121,381.0
30.033680816,385.0
30.112462511,457.0
30.191244206,431.0
30.270025901,418.0
30.348807596,432.0
30.427589291,440.0
30.506370986,518.0
30.585152681,549.0
30.663934376,527.0
30.742716071,538.0
30.821497767,583.0
30.900279462,542.0
30.979061157,582.0
31.057842852,669.0
31.136624547,725.0
31.215406242,849.0
31.294187937,1179.0
31.372969632,2215.0
31.451751327,5108.0
31.530533022,13774.0
31.609314717,17621.0
31.688096412,13509.0
31.766878107,6342.0
31.845659802,2279.0
31.924441497,1128.0
32.003223192,810.0
32.082004887,638.0
32.160786582,611.0
32.239568277,559.0
32.318349972,535.0
32.397131667,452.0
32.475913362,507.0
32.554695057,433.0
32.633476752,456.0
32.712258447,452.0
32.791040142,419.0
32.869821837,380.0
32.948603532,441.0
33.027385227,425.0
33.106166922,431.0
33.184948617,370.0
33.263730312,390.0
33.342512007,384.0
33.421293702,362.0
33.500075397,372.0
33.578857092,385.0
33.657638787,396.0
33.736420482,422.0
33.815202177,405.0
33.893983872,398.0
33.972765567,408.0
34.051547263,407.0
34.130328958,419.0
34.209110653,466.0
34.287892348,429.0
34.366674043,410.0
34.445455738,439.0
34.524237433,353.0
34.603019128,376.0
34.681800823,418.0
34.760582518,378.0
34.839364213,369.0
34.918145908,348.0
34.996927603,339.0
35.075709298,386.0
35.154490993,374.0
35.233272688,361.0
35.312054383,343.0
35.390836078,346.0
35.469617773,327.0
35.548399468,272.0
35.627181163,306.0
35.705962858,321.0
35.784744553,361.0
35.863526248,337.0
35.942307943,341.0
36.021089638,281.0
36.099871333,311.0
36.178653028,329.0
36.257434723,309.0
36.336216418,316.0
36.414998113,327.0
36.493779808,260.0
36.572561503,296.0
36.651343198,315.0
36.730124893,343.0
36.808906588,324.0
36.887688283,302.0
36.966469978,292.0
37.045251673,298.0
37.124033368,331.0
37.202815063,291.0
37.281596759,316.0
37.360378454,290.0
37.439160149,307.0
37.517941844,309.0
37.596723539,304.0
37.675505234,344.0
37.754286929,362.0
37.833068624,331.0
37.911850319,323.0
37.990632014,299.0
38.069413709,330.0
38.148195404,387.0
38.226977099,346.0
38.305758794,365.0
38.384540489,352.0
38.463322184,337.0
38.542103879,380.0
38.620885574,422.0
38.699667269,589.0
38.778448964,949.0
38.857230659,2245.0
38.936012354,6099.0
39.014794049,4209.0
39.093575744,2216.0
39.172357439,722.0
39.251139134,449.0
39.329920829,388.0
39.408702524,361.0
39.487484219,356.0
39.566265914,305.0
39.645047609,311.0
39.723829304,306.0
39.802610999,315.0
39.881392694,283.0
39.960174389,320.0
40.038956084,308.0
40.117737779,272.0
40.196519474,275.0
40.275301169,255.0
40.354082864,272.0
40.432864560,271.0
40.511646255,287.0
40.590427950,279.0
40.669209645,284.0
40.747991340,284.0
40.826773035,310.0
40.905554730,235.0
40.984336425,276.0
41.063118120,254.0
41.141899815,281.0
41.220681510,260.0
41.299463205,264.0
41.378244900,256.0
41.457026595,292.0
41.535808290,265.0
41.614589985,243.0
41.693371680,260.0
41.772153375,265.0
41.850935070,245.0
41.929716765,246.0
42.008498460,268.0
42.087280155,272.0
42.166061850,284.0
42.244843545,285.0
42.323625240,278.0
42.402406935,278.0
42.481188630,249.0
42.559970325,242.0
42.638752020,242.0
42.717533715,248.0
42.796315410,229.0
42.875097105,236.0
42.953878800,223.0
43.032660495,266.0
43.111442190,273.0
43.190223885,241.0
43.269005580,247.0
43.347787275,280.0
43.426568970,248.0
43.505350665,247.0
43.584132360,276.0
43.662914056,262.0
43.741695751,297.0
43.820477446,283.0
43.899259141,241.0
43.978040836,268.0
44.056822531,249.0
44.135604226,261.0
44.214385921,309.0
44.293167616,286.0
44.371949311,287.0
44.450731006,315.0
44.529512701,318.0
44.608294396,345.0
44.687076091,369.0
44.765857786,452.0
44.844639481,667.0
44.923421176,1345.0
45.002202871,1839.0
45.080984566,1951.0
45.159766261,2071.0
45.238547956,2237.0
45.317329651,2557.0
45.396111346,3846.0
45.474893041,3286.0
45.553674736,2296.0
45.632456431,917.0
45.711238126,515.0
45.790019821,380.0
45.868801516,302.0
45.947583211,309.0
46.026364906,273.0
46.105146601,282.0
46.183928296,239.0
46.262709991,235.0
46.341491686,258.0
46.420273381,241.0
46.499055076,226.0
46.577836771,258.0
46.656618466,233.0
46.735400161,211.0
46.814181857,269.0
46.892963552,249.0
46.971745247,243.0
47.050526942,229.0
47.129308637,261.0
47.208090332,255.0
47.286872027,215.0
47.365653722,242.0
47.444435417,240.0
47.523217112,203.0
47.601998807,213.0
47.680780502,209.0
47.759562197,184.0
47.838343892,214.0
47.917125587,214.0
47.995907282,231.0
48.074688977,216.0
48.153470672,207.0
48.232252367,229.0
48.311034062,220.0
48.389815757,183.0
48.468597452,222.0
48.547379147,202.0
48.626160842,215.0
48.704942537,187.0
48.783724232,234.0
48.862505927,222.0
48.941287622,215.0
49.020069317,213.0
49.098851012,190.0
49.177632707,202.0
49.256414402,239.0
49.335196097,208.0
49.413977792,242.0
49.492759487,220.0
49.571541182,188.0
49.650322877,197.0
49.729104572,199.0
49.807886267,184.0
49.886667962,229.0
49.965449657,217.0
50.044231353,214.0
50.123013048,219.0
50.201794743,205.0
50.280576438,216.0
50.359358133,225.0
50.438139828,238.0
50.516921523,286.0
50.595703218,355.0
50.674484913,527.0
50.753266608,706.0
50.832048303,851.0
50.910829998,912.0
50.989611693,1050.0
51.068393388,1179.0
51.147175083,1062.0
51.225956778,656.0
51.304738473,493.0
51.383520168,266.0
51.462301863,246.0
51.541083558,215.0
51.619865253,195.0
51.698646948,221.0
51.777428643,196.0
51.856210338,187.0
51.934992033,192.0
52.013773728,198.0
52.092555423,178.0
52.171337118,194.0
52.250118813,174.0
52.328900508,197.0
52.407682203,160.0
52.486463898,197.0
52.565245593,191.0
52.644027288,203.0
52.722808983,204.0
52.801590678,230.0
52.880372373,166.0
52.959154068,219.0
53.037935763,159.0
53.116717458,169.0
53.195499153,169.0
53.274280849,187.0
53.353062544,177.0
53.431844239,209.0
53.510625934,193.0
53.589407629,195.0
53.668189324,196.0
53.746971019,180.0
53.825752714,149.0
53.904534409,174.0
53.983316104,182.0
54.062097799,185.0
54.140879494,176.0
54.219661189,172.0
54.298442884,215.0
54.377224579,200.0
54.456006274,189.0
54.534787969,200.0
54.613569664,204.0
54.692351359,214.0
54.771133054,216.0
54.849914749,200.0
54.928696444,185.0
55.007478139,221.0
55.086259834,206.0
55.165041529,220.0
55.243823224,196.0
55.322604919,215.0
55.401386614,205.0
55.480168309,238.0
55.558950004,255.0
55.637731699,255.0
55.716513394,288.0
55.795295089,397.0
55.874076784,509.0
55.952858479,1031.0
56.031640174,2216.0
56.110421869,2467.0
56.189203564,3235.0
56.267985259,4193.0
56.346766954,4599.0
56.425548650,2600.0
56.504330345,2059.0
56.583112040,765.0
56.661893735,435.0
56.740675430,310.0
56.819457125,249.0
56.898238820,268.0
56.977020515,215.0
57.055802210,198.0
57.134583905,214.0
57.213365600,184.0
57.292147295,191.0
57.370928990,185.0
57.449710685,186.0
57.528492380,196.0
57.607274075,186.0
57.686055770,197.0
57.764837465,195.0
57.843619160,184.0
57.922400855,156.0
58.001182550,166.0
58.079964245,164.0
58.158745940,172.0
58.237527635,152.0
58.316309330,136.0
58.395091025,164.0
58.473872720,162.0
58.552654415,152.0
58.631436110,155.0
58.710217805,166.0
58.788999500,190.0
58.867781195,153.0
58.946562890,152.0
59.025344585,151.0
59.104126280,161.0
59.182907975,157.0
59.261689670,172.0
59.340471365,138.0
59.419253060,146.0
59.498034755,173.0
59.576816450,152.0
59.655598146,159.0
59.734379841,149.0
59.813161536,158.0
59.891943231,166.0
59.970724926,148.0
60.049506621,186.0
60.128288316,148.0
60.207070011,145.0
60.285851706,174.0
60.364633401,152.0
60.443415096,151.0
60.522196791,169.0
60.600978486,162.0
60.679760181,138.0
60.758541876,155.0
60.837323571,173.0
60.916105266,161.0
60.994886961,152.0
61.073668656,175.0
61.152450351,148.0
61.231232046,184.0
61.310013741,158.0
61.388795436,145.0
61.467577131,157.0
61.546358826,144.0
61.625140521,159.0
61.703922216,165.0
61.782703911,155.0
61.861485606,159.0
61.940267301,151.0
62.019048996,125.0
62.097830691,161.0
62.176612386,142.0
62.255394081,144.0
62.334175776,142.0
62.412957471,150.0
62.491739166,144.0
62.570520861,172.0
62.649302556,156.0
62.728084251,161.0
62.806865947,160.0
62.885647642,151.0
62.964429337,141.0
63.043211032,145.0
63.121992727,147.0
63.200774422,145.0
63.279556117,158.0
63.358337812,136.0
63.437119507,143.0
63.515901202,118.0
63.594682897,165.0
63.673464592,159.0
63.752246287,146.0
63.831027982,167.0
63.909809677,159.0
63.988591372,144.0
64.067373067,125.0
64.146154762,136.0
64.224936457,150.0
64.303718152,159.0
64.382499847,147.0
64.461281542,145.0
64.540063237,182.0
64.618844932,145.0
64.697626627,139.0
64.776408322,176.0
64.855190017,166.0
64.933971712,151.0
65.012753407,146.0
65.091535102,137.0
65.170316797,179.0
65.249098492,148.0
65.327880187,176.0
65.406661882,217.0
65.485443577,248.0
65.564225272,285.0
65.643006967,523.0
65.721788662,1090.0
65.800570357,1944.0
65.879352052,1605.0
65.958133747,1721.0
66.036915443,1541.0
66.115697138,1350.0
66.194478833,1083.0
66.273260528,675.0
66.352042223,588.0
66.430823918,312.0
66.509605613,209.0
66.588387308,187.0
66.667169003,173.0
66.745950698,153.0
66.824732393,169.0
66.903514088,146.0
66.982295783,163.0
67.061077478,144.0
67.139859173,133.0
67.218640868,147.0
67.297422563,145.0
67.376204258,142.0
67.454985953,160.0
67.533767648,137.0
67.612549343,124.0
67.691331038,142.0
67.770112733,122.0
67.848894428,149.0
67.927676123,125.0
68.006457818,135.0
68.085239513,145.0
68.164021208,136.0
68.242802903,130.0
68.321584598,136.0
68.400366293,153.0
68.479147988,150.0
68.557929683,164.0
68.636711378,132.0
68.715493073,125.0
68.794274768,141.0
68.873056463,129.0
68.951838158,133.0
69.030619853,130.0
69.109401548,123.0
69.188183243,126.0
69.266964939,157.0
69.345746634,150.0
69.424528329,125.0
69.503310024,134.0
69.582091719,147.0
69.660873414,133.0
69.739655109,154.0
69.818436804,158.0
69.897218499,170.0
69.976000194,197.0
70.054781889,177.0
70.133563584,226.0
70.212345279,235.0
70.291126974,327.0
70.369908669,566.0
70.448690364,542.0
70.527472059,529.0
70.606253754,569.0
70.685035449,466.0
70.763817144,337.0
70.842598839,256.0
70.921380534,223.0
71.000162229,198.0
71.078943924,139.0
71.157725619,134.0
71.236507314,144.0
71.315289009,145.0
71.394070704,129.0
71.472852399,139.0
71.551634094,131.0
71.630415789,105.0
71.709197484,127.0
71.787979179,141.0
71.866760874,135.0
71.945542569,122.0
72.024324264,137.0
72.103105959,138.0
72.181887654,143.0
72.260669349,135.0
72.339451044,123.0
72.418232740,106.0
72.497014435,134.0
72.575796130,101.0
72.654577825,134.0
72.733359520,126.0
72.812141215,121.0
72.890922910,151.0
72.969704605,139.0
73.048486300,131.0
73.127267995,126.0
73.206049690,114.0
73.284831385,125.0
73.363613080,115.0
73.442394775,118.0
73.521176470,133.0
73.599958165,141.0
73.678739860,131.0
73.757521555,115.0
73.836303250,130.0
73.915084945,135.0
73.993866640,143.0
74.072648335,177.0
74.151430030,154.0
74.230211725,180.0
74.308993420,281.0
74.387775115,497.0
74.466556810,524.0
74.545338505,536.0
74.624120200,653.0
74.702901895,633.0
74.781683590,630.0
74.860465285,613.0
74.939246980,686.0
75.018028675,896.0
75.096810370,1051.0
75.175592065,1140.0
75.254373760,882.0
75.333155455,708.0
75.411937150,557.0
75.490718845,403.0
75.569500540,224.0
75.648282236,186.0
75.727063931,149.0
75.805845626,151.0
75.884627321,137.0
75.963409016,140.0
76.042190711,144.0
76.120972406,146.0
76.199754101,109.0
76.278535796,142.0
76.357317491,132.0
76.436099186,154.0
76.514880881,129.0
76.593662576,140.0
76.672444271,127.0
76.751225966,115.0
76.830007661,124.0
76.908789356,115.0
76.987571051,138.0
77.066352746,115.0
77.145134441,135.0
77.223916136,108.0
77.302697831,140.0
77.381479526,119.0
77.460261221,126.0
77.539042916,138.0
77.617824611,134.0
77.696606306,101.0
77.775388001,119.0
77.854169696,121.0
77.932951391,116.0
78.011733086,104.0
78.090514781,113.0
78.169296476,106.0
78.248078171,115.0
78.326859866,114.0
78.405641561,141.0
78.484423256,122.0
78.563204951,122.0
78.641986646,169.0
78.720768341,220.0
78.799550037,313.0
78.878331732,350.0
78.957113427,358.0
79.035895122,415.0
79.114676817,371.0
79.193458512,358.0
79.272240207,384.0
79.351021902,492.0
79.429803597,661.0
79.508585292,632.0
79.587366987,416.0
79.666148682,409.0
79.744930377,370.0
79.823712072,203.0
79.902493767,145.0
79.981275462,121.0
80.060057157,128.0
80.138838852,126.0
80.217620547,120.0
80.296402242,129.0
80.375183937,140.0
80.453965632,126.0
80.532747327,109.0
80.611529022,129.0
80.690310717,120.0
80.769092412,110.0
80.847874107,126.0
80.926655802,124.0
81.005437497,103.0
81.084219192,117.0
81.163000887,127.0
81.241782582,109.0
81.320564277,87.0
81.399345972,124.0
81.478127667,97.0
81.556909362,115.0
81.635691057,127.0
81.714472752,110.0
81.793254447,113.0
81.872036142,122.0
81.950817837,101.0
82.029599533,117.0
82.108381228,128.0
82.187162923,107.0
82.265944618,110.0
82.344726313,117.0
82.423508008,109.0
82.502289703,116.0
82.581071398,99.0
82.659853093,104.0
82.738634788,117.0
82.817416483,134.0
82.896198178,117.0
82.974979873,129.0
83.053761568,127.0
83.132543263,129.0
83.211324958,180.0
83.290106653,182.0
83.368888348,296.0
83.447670043,572.0
83.526451738,850.0
83.605233433,682.0
83.684015128,477.0
83.762796823,514.0
83.841578518,421.0
83.920360213,279.0
83.999141908,179.0
84.077923603,143.0
84.156705298,137.0
84.235486993,127.0
84.314268688,109.0
84.393050383,103.0
84.471832078,125.0
84.550613773,122.0
84.629395468,109.0
84.708177163,86.0
84.786958858,106.0
84.865740553,109.0
84.944522248,101.0
85.023303943,102.0
85.102085638,100.0
85.180867333,97.0
85.259649029,116.0
85.338430724,100.0
85.417212419,115.0
85.495994114,99.0
85.574775809,86.0
85.653557504,108.0
85.732339199,117.0
85.811120894,102.0
85.889902589,103.0
85.968684284,98.0
86.047465979,96.0
86.126247674,107.0
86.205029369,103.0
86.283811064,119.0
86.362592759,124.0
86.441374454,103.0
86.520156149,98.0
86.598937844,107.0
86.677719539,102.0
86.756501234,113.0
86.835282929,107.0
86.914064624,118.0
86.992846319,107.0
87.071628014,110.0
87.150409709,112.0
87.229191404,124.0
87.307973099,148.0
87.386754794,170.0
87.465536489,176.0
87.544318184,169.0
87.623099879,210.0
87.701881574,220.0
87.780663269,226.0
87.859444964,247.0
87.938226659,237.0
88.017008354,222.0
88.095790049,252.0
88.174571744,213.0
88.253353439,154.0
88.332135134,162.0
88.410916830,169.0
88.489698525,143.0
88.568480220,115.0
88.647261915,115.0
88.726043610,96.0
88.804825305,121.0
88.883607000,131.0
88.962388695,96.0
89.041170390,111.0
89.119952085,103.0
89.198733780,116.0
89.277515475,119.0
89.356297170,116.0
89.435078865,131.0
89.513860560,92.0
89.592642255,122.0
89.671423950,91.0
89.750205645,103.0
89.828987340,106.0
89.907769035,103.0
89.986550730,84.0