File: Experiment/4_CrystalGrowth/CaTio3.csv
[Measurement conditions]
Sample identification,
Comment - 1,"Configuration=Flat sample stage, Owner=User-1, Creation date=9/4/2017 1:38:11 PM"
Comment - 2,"Goniometer=PW3050/60 (Theta/Theta); Minimum step size 2Theta:0.001; Minimum step size Omega:0.001"
Comment - 3,"Sample stage=PW3071/xx Bracket"
Comment - 4,"Diffractometer system=XPERT-PRO"
Comment - 5,"Measurement program=C:\PANalytical\Data Collector\Programs\KTH_FSS.xrdmp, Identifier={66F37155-83A8-48B8-A400-FEDCA643D064}"
Anode material,Cu
K-Alpha1 wavelength,1.5405980
K-Alpha2 wavelength,1.5444260
Ratio K-Alpha2/K-Alpha1,0.500
Divergence slit,Fixed,0.38mm
Monochromator used,NO
Generator voltage, 40
Tube current, 30
File date and time,03/Jul/2020 12:45
Unit cell,
h k l, 0 0 0
Scan axis,Gonio
Scan range,10.009999997,89.999681013
Scan step size,0.0262606
No. of points, 3046
Scan type,CONTINUOUS
Time per step,126.990
[Scan points]
Angle,Intensity
10.023130280,1215.0
10.101911975,1203.0
10.180693670,1231.0
10.259475365,1250.0
10.338257060,1193.0
10.417038755,1140.0
10.495820450,1211.0
10.574602145,1189.0
10.653383840,1140.0
10.732165535,1206.0
10.810947230,1167.0
10.889728925,1208.0
10.968510620,1170.0
11.047292315,1120.0
11.126074010,1166.0
11.204855705,1169.0
11.283637400,1171.0
11.362419095,1097.0
11.441200790,1156.0
11.519982485,1180.0
11.598764180,1129.0
11.677545876,1123.0
11.756327571,1175.0
11.835109266,1055.0
11.913890961,1073.0
11.992672656,1120.0
12.071454351,1145.0
12.150236046,1096.0
12.229017741,1125.0
12.307799436,1147.0
12.386581131,1133.0
12.465362826,1123.0
12.544144521,1085.0
12.622926216,1107.0
12.701707911,1031.0
12.780489606,1044.0
12.859271301,1008.0
12.938052996,1068.0
13.016834691,1050.0
13.095616386,1069.0
13.174398081,1003.0
13.253179776,1011.0
13.331961471,1021.0
13.410743166,997.0
13.489524861,1069.0
13.568306556,1022.0
13.647088251,1051.0
13.725869946,1036.0
13.804651641,1034.0
13.883433336,993.0
13.962215031,1008.0
14.040996726,989.0
14.119778421,1001.0
14.198560116,982.0
14.277341811,968.0
14.356123506,968.0
14.434905201,999.0
14.513686896,962.0
14.592468591,1047.0
14.671250286,1029.0
14.750031981,1000.0
14.828813677,947.0
14.907595372,892.0
14.986377067,895.0
15.065158762,923.0
15.143940457,922.0
15.222722152,936.0
15.301503847,873.0
15.380285542,916.0
15.459067237,946.0
15.537848932,886.0
15.616630627,856.0
15.695412322,883.0
15.774194017,930.0
15.852975712,855.0
15.931757407,844.0
16.010539102,933.0
16.089320797,873.0
16.168102492,867.0
16.246884187,871.0
16.325665882,843.0
16.404447577,846.0
16.483229272,891.0
16.562010967,848.0
16.640792662,764.0
16.719574357,888.0
16.798356052,850.0
16.877137747,813.0
16.955919442,832.0
17.034701137,815.0
17.113482832,772.0
17.192264527,805.0
17.271046222,784.0
17.349827917,804.0
17.428609612,791.0
17.507391307,738.0
17.586173002,843.0
17.664954697,804.0
17.743736392,771.0
17.822518087,775.0
17.901299782,793.0
17.980081477,728.0
18.058863173,763.0
18.137644868,746.0
18.216426563,759.0
18.295208258,732.0
18.373989953,693.0
18.452771648,762.0
18.531553343,729.0
18.610335038,745.0
18.689116733,733.0
18.767898428,758.0
18.846680123,721.0
18.925461818,728.0
19.004243513,678.0
19.083025208,771.0
19.161806903,690.0
19.240588598,707.0
19.319370293,689.0
19.398151988,670.0
19.476933683,703.0
19.555715378,675.0
19.634497073,664.0
19.713278768,653.0
19.792060463,626.0
19.870842158,713.0
19.949623853,643.0
20.028405548,698.0
20.107187243,631.0
20.185968938,678.0
20.264750633,681.0
20.343532328,639.0
20.422314023,691.0
20.501095718,658.0
20.579877413,632.0
20.658659108,647.0
20.737440803,628.0
20.816222498,613.0
20.895004193,618.0
20.973785888,620.0
21.052567583,658.0
21.131349278,626.0
21.210130973,595.0
21.288912669,651.0
21.367694364,605.0
21.446476059,590.0
21.525257754,598.0
21.604039449,577.0
21.682821144,603.0
21.761602839,542.0
21.840384534,574.0
21.919166229,588.0
21.997947924,620.0
22.076729619,535.0
22.155511314,585.0
22.234293009,552.0
22.313074704,568.0
22.391856399,576.0
22.470638094,537.0
22.549419789,585.0
22.628201484,595.0
22.706983179,590.0
22.785764874,600.0
22.864546569,601.0
22.943328264,617.0
23.022109959,670.0
23.100891654,859.0
23.179673349,1511.0
23.258455044,2460.0
23.337236739,1187.0
23.416018434,634.0
23.494800129,576.0
23.573581824,556.0
23.652363519,554.0
23.731145214,515.0
23.809926909,525.0
23.888708604,525.0
23.967490299,492.0
24.046271994,536.0
24.125053689,530.0
24.203835384,519.0
24.282617079,481.0
24.361398774,515.0
24.440180470,497.0
24.518962165,476.0
24.597743860,484.0
24.676525555,481.0
24.755307250,467.0
24.834088945,494.0
24.912870640,452.0
24.991652335,494.0
25.070434030,492.0
25.149215725,455.0
25.227997420,453.0
25.306779115,429.0
25.385560810,487.0
25.464342505,466.0
25.543124200,453.0
25.621905895,476.0
25.700687590,466.0
25.779469285,433.0
25.858250980,546.0
25.937032675,569.0
26.015814370,823.0
26.094596065,675.0
26.173377760,524.0
26.252159455,495.0
26.330941150,492.0
26.409722845,458.0
26.488504540,452.0
26.567286235,455.0
26.646067930,452.0
26.724849625,434.0
26.803631320,420.0
26.882413015,454.0
26.961194710,444.0
27.039976405,461.0
27.118758100,442.0
27.197539795,475.0
27.276321490,472.0
27.355103185,490.0
27.433884880,637.0
27.512666575,567.0
27.591448270,440.0
27.670229966,425.0
27.749011661,409.0
27.827793356,387.0
27.906575051,428.0
27.985356746,411.0
28.064138441,399.0
28.142920136,420.0
28.221701831,408.0
28.300483526,414.0
28.379265221,378.0
28.458046916,423.0
28.536828611,384.0
28.615610306,425.0
28.694392001,399.0
28.773173696,398.0
28.851955391,392.0
28.930737086,374.0
29.009518781,391.0
29.088300476,395.0
29.167082171,416.0
29.245863866,399.0
29.324645561,397.0
29.403427256,434.0
29.482208951,364.0
29.560990646,414.0
29.639772341,407.0
29.718554036,406.0
29.797335731,403.0
29.876117426,404.0
29.954899121,349.0
30.033680816,371.0
30.112462511,384.0
30.191244206,366.0
30.270025901,392.0
30.348807596,367.0
30.427589291,372.0
30.506370986,383.0
30.585152681,374.0
30.663934376,358.0
30.742716071,375.0
30.821497767,350.0
30.900279462,349.0
30.979061157,322.0
31.057842852,341.0
31.136624547,344.0
31.215406242,352.0
31.294187937,338.0
31.372969632,334.0
31.451751327,344.0
31.530533022,319.0
31.609314717,359.0
31.688096412,383.0
31.766878107,401.0
31.845659802,369.0
31.924441497,343.0
32.003223192,407.0
32.082004887,424.0
32.160786582,435.0
32.239568277,433.0
32.318349972,424.0
32.397131667,503.0
32.475913362,447.0
32.554695057,481.0
32.633476752,494.0
32.712258447,685.0
32.791040142,1183.0
32.869821837,2991.0
32.948603532,4261.0
33.027385227,6036.0
33.106166922,13909.0
33.184948617,9084.0
33.263730312,5014.0
33.342512007,2531.0
33.421293702,1022.0
33.500075397,612.0
33.578857092,483.0
33.657638787,451.0
33.736420482,393.0
33.815202177,398.0
33.893983872,369.0
33.972765567,385.0
34.051547263,357.0
34.130328958,376.0
34.209110653,327.0
34.287892348,342.0
34.366674043,356.0
34.445455738,360.0
34.524237433,330.0
34.603019128,347.0
34.681800823,362.0
34.760582518,306.0
34.839364213,328.0
34.918145908,381.0
34.996927603,463.0
35.075709298,396.0
35.154490993,332.0
35.233272688,278.0
35.312054383,320.0
35.390836078,320.0
35.469617773,313.0
35.548399468,298.0
35.627181163,323.0
35.705962858,313.0
35.784744553,295.0
35.863526248,323.0
35.942307943,321.0
36.021089638,358.0
36.099871333,402.0
36.178653028,323.0
36.257434723,320.0
36.336216418,283.0
36.414998113,263.0
36.493779808,289.0
36.572561503,337.0
36.651343198,267.0
36.730124893,268.0
36.808906588,267.0
36.887688283,323.0
36.966469978,393.0
37.045251673,403.0
37.124033368,391.0
37.202815063,429.0
37.281596759,445.0
37.360378454,375.0
37.439160149,310.0
37.517941844,282.0
37.596723539,269.0
37.675505234,279.0
37.754286929,277.0
37.833068624,278.0
37.911850319,277.0
37.990632014,299.0
38.069413709,295.0
38.148195404,273.0
38.226977099,263.0
38.305758794,272.0
38.384540489,257.0
38.463322184,267.0
38.542103879,310.0
38.620885574,273.0
38.699667269,266.0
38.778448964,272.0
38.857230659,416.0
38.936012354,508.0
39.014794049,691.0
39.093575744,1092.0
39.172357439,856.0
39.251139134,541.0
39.329920829,316.0
39.408702524,293.0
39.487484219,247.0
39.566265914,291.0
39.645047609,272.0
39.723829304,227.0
39.802610999,237.0
39.881392694,235.0
39.960174389,253.0
40.038956084,272.0
40.117737779,206.0
40.196519474,209.0
40.275301169,242.0
40.354082864,280.0
40.432864560,288.0
40.511646255,306.0
40.590427950,425.0
40.669209645,839.0
40.747991340,748.0
40.826773035,639.0
40.905554730,516.0
40.984336425,768.0
41.063118120,593.0
41.141899815,440.0
41.220681510,301.0
41.299463205,247.0
41.378244900,264.0
41.457026595,262.0
41.535808290,222.0
41.614589985,207.0
41.693371680,240.0
41.772153375,223.0
41.850935070,218.0
41.929716765,199.0
42.008498460,225.0
42.087280155,261.0
42.166061850,202.0
42.244843545,190.0
42.323625240,241.0
42.402406935,228.0
42.481188630,254.0
42.559970325,394.0
42.638752020,477.0
42.717533715,385.0
42.796315410,250.0
42.875097105,251.0
42.953878800,207.0
43.032660495,217.0
43.111442190,203.0
43.190223885,226.0
43.269005580,222.0
43.347787275,217.0
43.426568970,197.0
43.505350665,208.0
43.584132360,188.0
43.662914056,242.0
43.741695751,207.0
43.820477446,216.0
43.899259141,243.0
43.978040836,218.0
44.056822531,247.0
44.135604226,397.0
44.214385921,375.0
44.293167616,382.0
44.371949311,355.0
44.450731006,294.0
44.529512701,294.0
44.608294396,215.0
44.687076091,212.0
44.765857786,200.0
44.844639481,208.0
44.923421176,200.0
45.002202871,186.0
45.080984566,200.0
45.159766261,182.0
45.238547956,199.0
45.317329651,196.0
45.396111346,193.0
45.474893041,217.0
45.553674736,209.0
45.632456431,206.0
45.711238126,213.0
45.790019821,225.0
45.868801516,241.0
45.947583211,226.0
46.026364906,253.0
46.105146601,222.0
46.183928296,227.0
46.262709991,195.0
46.341491686,233.0
46.420273381,195.0
46.499055076,216.0
46.577836771,230.0
46.656618466,214.0
46.735400161,252.0
46.814181857,241.0
46.892963552,255.0
46.971745247,277.0
47.050526942,248.0
47.129308637,305.0
47.208090332,389.0
47.286872027,609.0
47.365653722,1296.0
47.444435417,3903.0
47.523217112,6302.0
47.601998807,4923.0
47.680780502,2801.0
47.759562197,961.0
47.838343892,476.0
47.917125587,310.0
47.995907282,267.0
48.074688977,248.0
48.153470672,215.0
48.232252367,249.0
48.311034062,218.0
48.389815757,212.0
48.468597452,202.0
48.547379147,201.0
48.626160842,244.0
48.704942537,198.0
48.783724232,235.0
48.862505927,264.0
48.941287622,422.0
49.020069317,442.0
49.098851012,439.0
49.177632707,328.0
49.256414402,238.0
49.335196097,186.0
49.413977792,198.0
49.492759487,185.0
49.571541182,189.0
49.650322877,205.0
49.729104572,174.0
49.807886267,199.0
49.886667962,212.0
49.965449657,185.0
50.044231353,163.0
50.123013048,171.0
50.201794743,179.0
50.280576438,193.0
50.359358133,193.0
50.438139828,160.0
50.516921523,210.0
50.595703218,162.0
50.674484913,180.0
50.753266608,169.0
50.832048303,184.0
50.910829998,174.0
50.989611693,166.0
51.068393388,186.0
51.147175083,173.0
51.225956778,185.0
51.304738473,167.0
51.383520168,180.0
51.462301863,176.0
51.541083558,145.0
51.619865253,157.0
51.698646948,168.0
51.777428643,189.0
51.856210338,205.0
51.934992033,184.0
52.013773728,265.0
52.092555423,251.0
52.171337118,262.0
52.250118813,256.0
52.328900508,251.0
52.407682203,235.0
52.486463898,220.0
52.565245593,143.0
52.644027288,176.0
52.722808983,163.0
52.801590678,142.0
52.880372373,165.0
52.959154068,205.0
53.037935763,195.0
53.116717458,194.0
53.195499153,285.0
53.274280849,392.0
53.353062544,319.0
53.431844239,367.0
53.510625934,437.0
53.589407629,443.0
53.668189324,362.0
53.746971019,280.0
53.825752714,230.0
53.904534409,183.0
53.983316104,205.0
54.062097799,148.0
54.140879494,153.0
54.219661189,145.0
54.298442884,250.0
54.377224579,231.0
54.456006274,224.0
54.534787969,208.0
54.613569664,253.0
54.692351359,476.0
54.771133054,406.0
54.849914749,355.0
54.928696444,231.0
55.007478139,210.0
55.086259834,189.0
55.165041529,224.0
55.243823224,190.0
55.322604919,195.0
55.401386614,183.0
55.480168309,151.0
55.558950004,136.0
55.637731699,145.0
55.716513394,160.0
55.795295089,138.0
55.874076784,174.0
55.952858479,133.0
56.031640174,148.0
56.110421869,178.0
56.189203564,129.0
56.267985259,160.0
56.346766954,146.0
56.425548650,159.0
56.504330345,139.0
56.583112040,177.0
56.661893735,162.0
56.740675430,170.0
56.819457125,144.0
56.898238820,161.0
56.977020515,170.0
57.055802210,134.0
57.134583905,155.0
57.213365600,148.0
57.292147295,145.0
57.370928990,165.0
57.449710685,158.0
57.528492380,174.0
57.607274075,171.0
57.686055770,191.0
57.764837465,160.0
57.843619160,158.0
57.922400855,163.0
58.001182550,153.0
58.079964245,143.0
58.158745940,150.0
58.237527635,144.0
58.316309330,146.0
58.395091025,186.0
58.473872720,193.0
58.552654415,194.0
58.631436110,229.0
58.710217805,345.0
58.788999500,740.0
58.867781195,1606.0
58.946562890,1517.0
59.025344585,2200.0
59.104126280,1490.0
59.182907975,1673.0
59.261689670,2459.0
59.340471365,2886.0
59.419253060,1824.0
59.498034755,1556.0
59.576816450,721.0
59.655598146,333.0
59.734379841,241.0
59.813161536,222.0
59.891943231,168.0
59.970724926,174.0
60.049506621,175.0
60.128288316,172.0
60.207070011,157.0
60.285851706,165.0
60.364633401,167.0
60.443415096,169.0
60.522196791,158.0
60.600978486,192.0
60.679760181,177.0
60.758541876,164.0
60.837323571,145.0
60.916105266,141.0
60.994886961,156.0
61.073668656,131.0
61.152450351,165.0
61.231232046,156.0
61.310013741,128.0
61.388795436,135.0
61.467577131,154.0
61.546358826,149.0
61.625140521,149.0
61.703922216,169.0
61.782703911,163.0
61.861485606,189.0
61.940267301,161.0
62.019048996,169.0
62.097830691,190.0
62.176612386,157.0
62.255394081,132.0
62.334175776,139.0
62.412957471,131.0
62.491739166,151.0
62.570520861,147.0
62.649302556,114.0
62.728084251,149.0
62.806865947,147.0
62.885647642,170.0
62.964429337,169.0
63.043211032,139.0
63.121992727,151.0
63.200774422,195.0
63.279556117,157.0
63.358337812,127.0
63.437119507,150.0
63.515901202,132.0
63.594682897,124.0
63.673464592,120.0
63.752246287,132.0
63.831027982,130.0
63.909809677,112.0
63.988591372,146.0
64.067373067,156.0
64.146154762,138.0
64.224936457,104.0
64.303718152,125.0
64.382499847,113.0
64.461281542,147.0
64.540063237,140.0
64.618844932,139.0
64.697626627,153.0
64.776408322,140.0
64.855190017,97.0
64.933971712,130.0
65.012753407,124.0
65.091535102,144.0
65.170316797,128.0
65.249098492,171.0
65.327880187,142.0
65.406661882,204.0
65.485443577,229.0
65.564225272,219.0
65.643006967,198.0
65.721788662,156.0
65.800570357,129.0
65.879352052,112.0
65.958133747,146.0
66.036915443,148.0
66.115697138,126.0
66.194478833,122.0
66.273260528,114.0
66.352042223,123.0
66.430823918,135.0
66.509605613,99.0
66.588387308,98.0
66.667169003,130.0
66.745950698,122.0
66.824732393,147.0
66.903514088,109.0
66.982295783,160.0
67.061077478,125.0
67.139859173,131.0
67.218640868,135.0
67.297422563,109.0
67.376204258,159.0
67.454985953,139.0
67.533767648,122.0
67.612549343,121.0
67.691331038,101.0
67.770112733,117.0
67.848894428,120.0
67.927676123,120.0
68.006457818,103.0
68.085239513,115.0
68.164021208,107.0
68.242802903,107.0
68.321584598,114.0
68.400366293,129.0
68.479147988,138.0
68.557929683,135.0
68.636711378,142.0
68.715493073,130.0
68.794274768,157.0
68.873056463,200.0
68.951838158,392.0
69.030619853,462.0
69.109401548,411.0
69.188183243,381.0
69.266964939,386.0
69.345746634,563.0
69.424528329,1248.0
69.503310024,1597.0
69.582091719,901.0
69.660873414,1086.0
69.739655109,702.0
69.818436804,588.0
69.897218499,433.0
69.976000194,336.0
70.054781889,299.0
70.133563584,222.0
70.212345279,207.0
70.291126974,167.0
70.369908669,184.0
70.448690364,172.0
70.527472059,186.0
70.606253754,122.0
70.685035449,119.0
70.763817144,127.0
70.842598839,117.0
70.921380534,147.0
71.000162229,119.0
71.078943924,123.0
71.157725619,115.0
71.236507314,116.0
71.315289009,118.0
71.394070704,129.0
71.472852399,152.0
71.551634094,144.0
71.630415789,115.0
71.709197484,115.0
71.787979179,122.0
71.866760874,122.0
71.945542569,93.0
72.024324264,119.0
72.103105959,117.0
72.181887654,131.0
72.260669349,140.0
72.339451044,114.0
72.418232740,125.0
72.497014435,128.0
72.575796130,112.0
72.654577825,116.0
72.733359520,119.0
72.812141215,109.0
72.890922910,133.0
72.969704605,162.0
73.048486300,178.0
73.127267995,203.0
73.206049690,190.0
73.284831385,244.0
73.363613080,156.0
73.442394775,163.0
73.521176470,159.0
73.599958165,139.0
73.678739860,134.0
73.757521555,102.0
73.836303250,129.0
73.915084945,139.0
73.993866640,134.0
74.072648335,159.0
74.151430030,191.0
74.230211725,160.0
74.308993420,143.0
74.387775115,158.0
74.466556810,143.0
74.545338505,146.0
74.624120200,126.0
74.702901895,131.0
74.781683590,117.0
74.860465285,109.0
74.939246980,117.0
75.018028675,111.0
75.096810370,108.0
75.175592065,128.0
75.254373760,106.0
75.333155455,110.0
75.411937150,136.0
75.490718845,148.0
75.569500540,137.0
75.648282236,105.0
75.727063931,114.0
75.805845626,131.0
75.884627321,106.0
75.963409016,108.0
76.042190711,109.0
76.120972406,111.0
76.199754101,95.0
76.278535796,125.0
76.357317491,145.0
76.436099186,110.0
76.514880881,127.0
76.593662576,124.0
76.672444271,114.0
76.751225966,106.0
76.830007661,123.0
76.908789356,108.0
76.987571051,102.0
77.066352746,114.0
77.145134441,135.0
77.223916136,123.0
77.302697831,123.0
77.381479526,110.0
77.460261221,110.0
77.539042916,118.0
77.617824611,120.0
77.696606306,115.0
77.775388001,135.0
77.854169696,112.0
77.932951391,101.0
78.011733086,118.0
78.090514781,103.0
78.169296476,119.0
78.248078171,107.0
78.326859866,111.0
78.405641561,101.0
78.484423256,107.0
78.563204951,138.0
78.641986646,161.0
78.720768341,238.0
78.799550037,296.0
78.878331732,267.0
78.957113427,352.0
79.035895122,547.0
79.114676817,768.0
79.193458512,851.0
79.272240207,668.0
79.351021902,630.0
79.429803597,613.0
79.508585292,383.0
79.587366987,251.0
79.666148682,222.0
79.744930377,161.0
79.823712072,125.0
79.902493767,169.0
79.981275462,153.0
80.060057157,150.0
80.138838852,130.0
80.217620547,127.0
80.296402242,140.0
80.375183937,170.0
80.453965632,122.0
80.532747327,142.0
80.611529022,133.0
80.690310717,112.0
80.769092412,121.0
80.847874107,121.0
80.926655802,109.0
81.005437497,111.0
81.084219192,88.0
81.163000887,91.0
81.241782582,92.0
81.320564277,97.0
81.399345972,76.0
81.478127667,102.0
81.556909362,84.0
81.635691057,99.0
81.714472752,101.0
81.793254447,109.0
81.872036142,88.0
81.950817837,81.0
82.029599533,110.0
82.108381228,103.0
82.187162923,117.0
82.265944618,101.0
82.344726313,106.0
82.423508008,96.0
82.502289703,107.0
82.581071398,99.0
82.659853093,107.0
82.738634788,104.0
82.817416483,120.0
82.896198178,112.0
82.974979873,147.0
83.053761568,133.0
83.132543263,94.0
83.211324958,117.0
83.290106653,119.0
83.368888348,106.0
83.447670043,115.0
83.526451738,100.0
83.605233433,92.0
83.684015128,96.0
83.762796823,104.0
83.841578518,93.0
83.920360213,85.0
83.999141908,94.0
84.077923603,85.0
84.156705298,91.0
84.235486993,101.0
84.314268688,136.0
84.393050383,106.0
84.471832078,95.0
84.550613773,122.0
84.629395468,100.0
84.708177163,122.0
84.786958858,158.0
84.865740553,177.0
84.944522248,174.0
85.023303943,178.0
85.102085638,125.0
85.180867333,164.0
85.259649029,162.0
85.338430724,115.0
85.417212419,114.0
85.495994114,111.0
85.574775809,97.0
85.653557504,107.0
85.732339199,110.0
85.811120894,89.0
85.889902589,102.0
85.968684284,91.0
86.047465979,115.0
86.126247674,102.0
86.205029369,83.0
86.283811064,96.0
86.362592759,97.0
86.441374454,85.0
86.520156149,109.0
86.598937844,94.0
86.677719539,84.0
86.756501234,110.0
86.835282929,100.0
86.914064624,84.0
86.992846319,98.0
87.071628014,112.0
87.150409709,75.0
87.229191404,102.0
87.307973099,93.0
87.386754794,81.0
87.465536489,86.0
87.544318184,105.0
87.623099879,114.0
87.701881574,92.0
87.780663269,116.0
87.859444964,119.0
87.938226659,138.0
88.017008354,227.0
88.095790049,297.0
88.174571744,246.0
88.253353439,209.0
88.332135134,238.0
88.410916830,187.0
88.489698525,171.0
88.568480220,124.0
88.647261915,125.0
88.726043610,165.0
88.804825305,248.0
88.883607000,335.0
88.962388695,253.0
89.041170390,189.0
89.119952085,194.0
89.198733780,216.0
89.277515475,206.0
89.356297170,176.0
89.435078865,146.0
89.513860560,149.0
89.592642255,174.0
89.671423950,156.0
89.750205645,106.0
89.828987340,100.0
89.907769035,125.0
89.986550730,119.0