File: Experiment/4_CrystalGrowth/SrTiO3.csv
[Measurement conditions]
Sample identification,
Comment - 1,"Configuration=Flat sample stage, Owner=User-1, Creation date=9/4/2017 1:38:11 PM"
Comment - 2,"Goniometer=PW3050/60 (Theta/Theta); Minimum step size 2Theta:0.001; Minimum step size Omega:0.001"
Comment - 3,"Sample stage=PW3071/xx Bracket"
Comment - 4,"Diffractometer system=XPERT-PRO"
Comment - 5,"Measurement program=C:\PANalytical\Data Collector\Programs\KTH_FSS.xrdmp, Identifier={25D02D24-B7D2-4E7B-8B86-82B391BC07B0}"
Anode material,Cu
K-Alpha1 wavelength,1.5405980
K-Alpha2 wavelength,1.5444260
Ratio K-Alpha2/K-Alpha1,0.500
Divergence slit,Fixed,0.38mm
Monochromator used,NO
Generator voltage, 40
Tube current, 30
File date and time,29/Jun/2020 09:49
Unit cell,
h k l, 0 0 0
Scan axis,Gonio
Scan range,10.009999997,89.999681013
Scan step size,0.0262606
No. of points, 3046
Scan type,CONTINUOUS
Time per step,126.990
[Scan points]
Angle,Intensity
10.023130280,1856.0
10.101911975,1909.0
10.180693670,1859.0
10.259475365,1878.0
10.338257060,1962.0
10.417038755,1800.0
10.495820450,1855.0
10.574602145,1807.0
10.653383840,1876.0
10.732165535,1894.0
10.810947230,1864.0
10.889728925,1926.0
10.968510620,1778.0
11.047292315,1840.0
11.126074010,1762.0
11.204855705,1859.0
11.283637400,1777.0
11.362419095,1771.0
11.441200790,1732.0
11.519982485,1764.0
11.598764180,1850.0
11.677545876,1811.0
11.756327571,1797.0
11.835109266,1766.0
11.913890961,1765.0
11.992672656,1763.0
12.071454351,1695.0
12.150236046,1718.0
12.229017741,1751.0
12.307799436,1789.0
12.386581131,1726.0
12.465362826,1680.0
12.544144521,1709.0
12.622926216,1777.0
12.701707911,1773.0
12.780489606,1708.0
12.859271301,1710.0
12.938052996,1666.0
13.016834691,1811.0
13.095616386,1714.0
13.174398081,1678.0
13.253179776,1658.0
13.331961471,1713.0
13.410743166,1712.0
13.489524861,1694.0
13.568306556,1630.0
13.647088251,1687.0
13.725869946,1683.0
13.804651641,1637.0
13.883433336,1673.0
13.962215031,1743.0
14.040996726,1746.0
14.119778421,1691.0
14.198560116,1783.0
14.277341811,1746.0
14.356123506,1834.0
14.434905201,1609.0
14.513686896,1637.0
14.592468591,1654.0
14.671250286,1636.0
14.750031981,1764.0
14.828813677,1759.0
14.907595372,1656.0
14.986377067,1648.0
15.065158762,1676.0
15.143940457,1565.0
15.222722152,1750.0
15.301503847,1598.0
15.380285542,1626.0
15.459067237,1654.0
15.537848932,1577.0
15.616630627,1685.0
15.695412322,1645.0
15.774194017,1591.0
15.852975712,1641.0
15.931757407,1646.0
16.010539102,1705.0
16.089320797,1733.0
16.168102492,1727.0
16.246884187,1809.0
16.325665882,1748.0
16.404447577,1757.0
16.483229272,1740.0
16.562010967,1696.0
16.640792662,1722.0
16.719574357,1647.0
16.798356052,1659.0
16.877137747,1609.0
16.955919442,1685.0
17.034701137,1670.0
17.113482832,1646.0
17.192264527,1686.0
17.271046222,1652.0
17.349827917,1667.0
17.428609612,1659.0
17.507391307,1680.0
17.586173002,1582.0
17.664954697,1668.0
17.743736392,1649.0
17.822518087,1622.0
17.901299782,1668.0
17.980081477,1643.0
18.058863173,1625.0
18.137644868,1634.0
18.216426563,1585.0
18.295208258,1585.0
18.373989953,1583.0
18.452771648,1648.0
18.531553343,1619.0
18.610335038,1722.0
18.689116733,1652.0
18.767898428,1625.0
18.846680123,1557.0
18.925461818,1623.0
19.004243513,1550.0
19.083025208,1633.0
19.161806903,1539.0
19.240588598,1635.0
19.319370293,1557.0
19.398151988,1727.0
19.476933683,1599.0
19.555715378,1693.0
19.634497073,1611.0
19.713278768,1565.0
19.792060463,1624.0
19.870842158,1584.0
19.949623853,1526.0
20.028405548,1562.0
20.107187243,1636.0
20.185968938,1553.0
20.264750633,1539.0
20.343532328,1435.0
20.422314023,1527.0
20.501095718,1526.0
20.579877413,1584.0
20.658659108,1575.0
20.737440803,1507.0
20.816222498,1599.0
20.895004193,1509.0
20.973785888,1530.0
21.052567583,1471.0
21.131349278,1504.0
21.210130973,1524.0
21.288912669,1497.0
21.367694364,1423.0
21.446476059,1399.0
21.525257754,1476.0
21.604039449,1520.0
21.682821144,1477.0
21.761602839,1554.0
21.840384534,1462.0
21.919166229,1512.0
21.997947924,1454.0
22.076729619,1425.0
22.155511314,1523.0
22.234293009,1476.0
22.313074704,1471.0
22.391856399,1486.0
22.470638094,1482.0
22.549419789,1438.0
22.628201484,1551.0
22.706983179,1731.0
22.785764874,2340.0
22.864546569,2470.0
22.943328264,1702.0
23.022109959,1633.0
23.100891654,1554.0
23.179673349,1485.0
23.258455044,1468.0
23.337236739,1484.0
23.416018434,1502.0
23.494800129,1597.0
23.573581824,1510.0
23.652363519,1462.0
23.731145214,1527.0
23.809926909,1466.0
23.888708604,1539.0
23.967490299,1527.0
24.046271994,1531.0
24.125053689,1498.0
24.203835384,1525.0
24.282617079,1421.0
24.361398774,1497.0
24.440180470,1585.0
24.518962165,1559.0
24.597743860,1459.0
24.676525555,1509.0
24.755307250,1404.0
24.834088945,1556.0
24.912870640,1487.0
24.991652335,1471.0
25.070434030,1533.0
25.149215725,1632.0
25.227997420,1697.0
25.306779115,1653.0
25.385560810,1623.0
25.464342505,1516.0
25.543124200,1515.0
25.621905895,1473.0
25.700687590,1535.0
25.779469285,1456.0
25.858250980,1502.0
25.937032675,1510.0
26.015814370,1476.0
26.094596065,1490.0
26.173377760,1461.0
26.252159455,1419.0
26.330941150,1404.0
26.409722845,1375.0
26.488504540,1500.0
26.567286235,1546.0
26.646067930,1538.0
26.724849625,1457.0
26.803631320,1370.0
26.882413015,1476.0
26.961194710,1422.0
27.039976405,1412.0
27.118758100,1370.0
27.197539795,1379.0
27.276321490,1382.0
27.355103185,1427.0
27.433884880,1563.0
27.512666575,1980.0
27.591448270,1778.0
27.670229966,1474.0
27.749011661,1446.0
27.827793356,1369.0
27.906575051,1415.0
27.985356746,1439.0
28.064138441,1428.0
28.142920136,1393.0
28.221701831,1446.0
28.300483526,1485.0
28.379265221,1502.0
28.458046916,1502.0
28.536828611,1512.0
28.615610306,1467.0
28.694392001,1383.0
28.773173696,1369.0
28.851955391,1473.0
28.930737086,1397.0
29.009518781,1399.0
29.088300476,1457.0
29.167082171,1426.0
29.245863866,1531.0
29.324645561,1501.0
29.403427256,1396.0
29.482208951,1483.0
29.560990646,1381.0
29.639772341,1356.0
29.718554036,1437.0
29.797335731,1410.0
29.876117426,1397.0
29.954899121,1392.0
30.033680816,1398.0
30.112462511,1418.0
30.191244206,1395.0
30.270025901,1414.0
30.348807596,1450.0
30.427589291,1415.0
30.506370986,1447.0
30.585152681,1389.0
30.663934376,1420.0
30.742716071,1311.0
30.821497767,1443.0
30.900279462,1410.0
30.979061157,1293.0
31.057842852,1402.0
31.136624547,1464.0
31.215406242,1437.0
31.294187937,1627.0
31.372969632,1872.0
31.451751327,2158.0
31.530533022,2045.0
31.609314717,1792.0
31.688096412,1904.0
31.766878107,1885.0
31.845659802,1983.0
31.924441497,1858.0
32.003223192,1809.0
32.082004887,1828.0
32.160786582,2235.0
32.239568277,2817.0
32.318349972,5235.0
32.397131667,14251.0
32.475913362,33323.0
32.554695057,21164.0
32.633476752,6931.0
32.712258447,3273.0
32.791040142,2209.0
32.869821837,1814.0
32.948603532,1737.0
33.027385227,1606.0
33.106166922,1462.0
33.184948617,1456.0
33.263730312,1478.0
33.342512007,1490.0
33.421293702,1464.0
33.500075397,1455.0
33.578857092,1521.0
33.657638787,1375.0
33.736420482,1374.0
33.815202177,1419.0
33.893983872,1418.0
33.972765567,1455.0
34.051547263,1393.0
34.130328958,1467.0
34.209110653,1356.0
34.287892348,1389.0
34.366674043,1381.0
34.445455738,1372.0
34.524237433,1276.0
34.603019128,1393.0
34.681800823,1379.0
34.760582518,1384.0
34.839364213,1353.0
34.918145908,1357.0
34.996927603,1367.0
35.075709298,1350.0
35.154490993,1414.0
35.233272688,1474.0
35.312054383,1366.0
35.390836078,1356.0
35.469617773,1365.0
35.548399468,1379.0
35.627181163,1356.0
35.705962858,1386.0
35.784744553,1370.0
35.863526248,1442.0
35.942307943,1439.0
36.021089638,1472.0
36.099871333,1516.0
36.178653028,1673.0
36.257434723,1623.0
36.336216418,1554.0
36.414998113,1555.0
36.493779808,1480.0
36.572561503,1497.0
36.651343198,1372.0
36.730124893,1386.0
36.808906588,1388.0
36.887688283,1279.0
36.966469978,1332.0
37.045251673,1343.0
37.124033368,1378.0
37.202815063,1299.0
37.281596759,1365.0
37.360378454,1315.0
37.439160149,1355.0
37.517941844,1313.0
37.596723539,1228.0
37.675505234,1358.0
37.754286929,1266.0
37.833068624,1341.0
37.911850319,1335.0
37.990632014,1203.0
38.069413709,1376.0
38.148195404,1339.0
38.226977099,1319.0
38.305758794,1309.0
38.384540489,1386.0
38.463322184,1355.0
38.542103879,1382.0
38.620885574,1369.0
38.699667269,1321.0
38.778448964,1294.0
38.857230659,1272.0
38.936012354,1418.0
39.014794049,1409.0
39.093575744,1367.0
39.172357439,1364.0
39.251139134,1407.0
39.329920829,1551.0
39.408702524,1410.0
39.487484219,1390.0
39.566265914,1387.0
39.645047609,1418.0
39.723829304,1432.0
39.802610999,1616.0
39.881392694,2099.0
39.960174389,4261.0
40.038956084,7804.0
40.117737779,5451.0
40.196519474,2868.0
40.275301169,1760.0
40.354082864,1607.0
40.432864560,1538.0
40.511646255,1506.0
40.590427950,1543.0
40.669209645,1423.0
40.747991340,1361.0
40.826773035,1372.0
40.905554730,1308.0
40.984336425,1295.0
41.063118120,1307.0
41.141899815,1286.0
41.220681510,1408.0
41.299463205,1440.0
41.378244900,1358.0
41.457026595,1331.0
41.535808290,1256.0
41.614589985,1362.0
41.693371680,1307.0
41.772153375,1259.0
41.850935070,1377.0
41.929716765,1333.0
42.008498460,1298.0
42.087280155,1334.0
42.166061850,1319.0
42.244843545,1398.0
42.323625240,1303.0
42.402406935,1350.0
42.481188630,1322.0
42.559970325,1334.0
42.638752020,1267.0
42.717533715,1333.0
42.796315410,1317.0
42.875097105,1330.0
42.953878800,1330.0
43.032660495,1261.0
43.111442190,1454.0
43.190223885,1351.0
43.269005580,1331.0
43.347787275,1295.0
43.426568970,1291.0
43.505350665,1209.0
43.584132360,1296.0
43.662914056,1394.0
43.741695751,1456.0
43.820477446,1448.0
43.899259141,1349.0
43.978040836,1370.0
44.056822531,1317.0
44.135604226,1464.0
44.214385921,1394.0
44.293167616,1362.0
44.371949311,1300.0
44.450731006,1239.0
44.529512701,1319.0
44.608294396,1348.0
44.687076091,1260.0
44.765857786,1397.0
44.844639481,1328.0
44.923421176,1323.0
45.002202871,1334.0
45.080984566,1351.0
45.159766261,1343.0
45.238547956,1333.0
45.317329651,1264.0
45.396111346,1331.0
45.474893041,1352.0
45.553674736,1415.0
45.632456431,1304.0
45.711238126,1262.0
45.790019821,1298.0
45.868801516,1301.0
45.947583211,1335.0
46.026364906,1421.0
46.105146601,1425.0
46.183928296,1559.0
46.262709991,1677.0
46.341491686,2059.0
46.420273381,3355.0
46.499055076,9267.0
46.577836771,11763.0
46.656618466,8360.0
46.735400161,4252.0
46.814181857,2235.0
46.892963552,1774.0
46.971745247,1529.0
47.050526942,1287.0
47.129308637,1413.0
47.208090332,1324.0
47.286872027,1251.0
47.365653722,1296.0
47.444435417,1308.0
47.523217112,1342.0
47.601998807,1276.0
47.680780502,1301.0
47.759562197,1354.0
47.838343892,1337.0
47.917125587,1292.0
47.995907282,1282.0
48.074688977,1248.0
48.153470672,1238.0
48.232252367,1255.0
48.311034062,1230.0
48.389815757,1290.0
48.468597452,1240.0
48.547379147,1206.0
48.626160842,1284.0
48.704942537,1307.0
48.783724232,1278.0
48.862505927,1257.0
48.941287622,1195.0
49.020069317,1265.0
49.098851012,1283.0
49.177632707,1284.0
49.256414402,1300.0
49.335196097,1310.0
49.413977792,1280.0
49.492759487,1253.0
49.571541182,1302.0
49.650322877,1271.0
49.729104572,1263.0
49.807886267,1287.0
49.886667962,1324.0
49.965449657,1414.0
50.044231353,1438.0
50.123013048,1389.0
50.201794743,1376.0
50.280576438,1293.0
50.359358133,1369.0
50.438139828,1299.0
50.516921523,1218.0
50.595703218,1280.0
50.674484913,1283.0
50.753266608,1284.0
50.832048303,1337.0
50.910829998,1269.0
50.989611693,1314.0
51.068393388,1291.0
51.147175083,1291.0
51.225956778,1337.0
51.304738473,1295.0
51.383520168,1328.0
51.462301863,1280.0
51.541083558,1211.0
51.619865253,1276.0
51.698646948,1320.0
51.777428643,1229.0
51.856210338,1302.0
51.934992033,1306.0
52.013773728,1352.0
52.092555423,1294.0
52.171337118,1295.0
52.250118813,1322.0
52.328900508,1501.0
52.407682203,1873.0
52.486463898,1662.0
52.565245593,1559.0
52.644027288,1309.0
52.722808983,1278.0
52.801590678,1255.0
52.880372373,1281.0
52.959154068,1275.0
53.037935763,1196.0
53.116717458,1232.0
53.195499153,1246.0
53.274280849,1269.0
53.353062544,1238.0
53.431844239,1221.0
53.510625934,1242.0
53.589407629,1215.0
53.668189324,1231.0
53.746971019,1228.0
53.825752714,1228.0
53.904534409,1272.0
53.983316104,1262.0
54.062097799,1214.0
54.140879494,1249.0
54.219661189,1261.0
54.298442884,1449.0
54.377224579,1448.0
54.456006274,1425.0
54.534787969,1483.0
54.613569664,1430.0
54.692351359,1270.0
54.771133054,1303.0
54.849914749,1289.0
54.928696444,1252.0
55.007478139,1321.0
55.086259834,1327.0
55.165041529,1344.0
55.243823224,1321.0
55.322604919,1287.0
55.401386614,1219.0
55.480168309,1221.0
55.558950004,1260.0
55.637731699,1297.0
55.716513394,1262.0
55.795295089,1301.0
55.874076784,1283.0
55.952858479,1271.0
56.031640174,1340.0
56.110421869,1357.0
56.189203564,1319.0
56.267985259,1303.0
56.346766954,1345.0
56.425548650,1326.0
56.504330345,1314.0
56.583112040,1305.0
56.661893735,1354.0
56.740675430,1377.0
56.819457125,1324.0
56.898238820,1367.0
56.977020515,1303.0
57.055802210,1304.0
57.134583905,1255.0
57.213365600,1318.0
57.292147295,1360.0
57.370928990,1549.0
57.449710685,1604.0
57.528492380,1738.0
57.607274075,1986.0
57.686055770,2275.0
57.764837465,4423.0
57.843619160,10466.0
57.922400855,6715.0
58.001182550,6636.0
58.079964245,3769.0
58.158745940,1922.0
58.237527635,1640.0
58.316309330,1441.0
58.395091025,1439.0
58.473872720,1343.0
58.552654415,1316.0
58.631436110,1370.0
58.710217805,1318.0
58.788999500,1312.0
58.867781195,1290.0
58.946562890,1297.0
59.025344585,1272.0
59.104126280,1215.0
59.182907975,1264.0
59.261689670,1302.0
59.340471365,1204.0
59.419253060,1193.0
59.498034755,1290.0
59.576816450,1283.0
59.655598146,1217.0
59.734379841,1314.0
59.813161536,1223.0
59.891943231,1234.0
59.970724926,1276.0
60.049506621,1301.0
60.128288316,1272.0
60.207070011,1251.0
60.285851706,1258.0
60.364633401,1247.0
60.443415096,1245.0
60.522196791,1208.0
60.600978486,1260.0
60.679760181,1234.0
60.758541876,1292.0
60.837323571,1275.0
60.916105266,1242.0
60.994886961,1194.0
61.073668656,1240.0
61.152450351,1239.0
61.231232046,1292.0
61.310013741,1242.0
61.388795436,1266.0
61.467577131,1302.0
61.546358826,1217.0
61.625140521,1249.0
61.703922216,1238.0
61.782703911,1277.0
61.861485606,1243.0
61.940267301,1226.0
62.019048996,1260.0
62.097830691,1209.0
62.176612386,1196.0
62.255394081,1278.0
62.334175776,1278.0
62.412957471,1178.0
62.491739166,1238.0
62.570520861,1229.0
62.649302556,1289.0
62.728084251,1243.0
62.806865947,1249.0
62.885647642,1315.0
62.964429337,1275.0
63.043211032,1280.0
63.121992727,1252.0
63.200774422,1177.0
63.279556117,1229.0
63.358337812,1227.0
63.437119507,1228.0
63.515901202,1174.0
63.594682897,1296.0
63.673464592,1181.0
63.752246287,1191.0
63.831027982,1294.0
63.909809677,1253.0
63.988591372,1254.0
64.067373067,1248.0
64.146154762,1311.0
64.224936457,1336.0
64.303718152,1317.0
64.382499847,1265.0
64.461281542,1233.0
64.540063237,1232.0
64.618844932,1228.0
64.697626627,1242.0
64.776408322,1219.0
64.855190017,1222.0
64.933971712,1200.0
65.012753407,1341.0
65.091535102,1219.0
65.170316797,1314.0
65.249098492,1195.0
65.327880187,1298.0
65.406661882,1244.0
65.485443577,1362.0
65.564225272,1271.0
65.643006967,1399.0
65.721788662,1255.0
65.800570357,1318.0
65.879352052,1278.0
65.958133747,1299.0
66.036915443,1280.0
66.115697138,1225.0
66.194478833,1268.0
66.273260528,1291.0
66.352042223,1258.0
66.430823918,1343.0
66.509605613,1301.0
66.588387308,1290.0
66.667169003,1237.0
66.745950698,1272.0
66.824732393,1242.0
66.903514088,1209.0
66.982295783,1265.0
67.061077478,1256.0
67.139859173,1283.0
67.218640868,1269.0
67.297422563,1248.0
67.376204258,1333.0
67.454985953,1303.0
67.533767648,1374.0
67.612549343,1466.0
67.691331038,1640.0
67.770112733,2287.0
67.848894428,5294.0
67.927676123,5554.0
68.006457818,3349.0
68.085239513,4052.0
68.164021208,2423.0
68.242802903,1622.0
68.321584598,1420.0
68.400366293,1304.0
68.479147988,1358.0
68.557929683,1220.0
68.636711378,1308.0
68.715493073,1316.0
68.794274768,1268.0
68.873056463,1273.0
68.951838158,1218.0
69.030619853,1305.0
69.109401548,1320.0
69.188183243,1239.0
69.266964939,1249.0
69.345746634,1259.0
69.424528329,1233.0
69.503310024,1260.0
69.582091719,1216.0
69.660873414,1229.0
69.739655109,1204.0
69.818436804,1301.0
69.897218499,1317.0
69.976000194,1281.0
70.054781889,1199.0
70.133563584,1220.0
70.212345279,1253.0
70.291126974,1195.0
70.369908669,1258.0
70.448690364,1253.0
70.527472059,1187.0
70.606253754,1218.0
70.685035449,1205.0
70.763817144,1209.0
70.842598839,1178.0
70.921380534,1185.0
71.000162229,1251.0
71.078943924,1210.0
71.157725619,1228.0
71.236507314,1220.0
71.315289009,1205.0
71.394070704,1215.0
71.472852399,1260.0
71.551634094,1208.0
71.630415789,1246.0
71.709197484,1270.0
71.787979179,1198.0
71.866760874,1237.0
71.945542569,1268.0
72.024324264,1207.0
72.103105959,1264.0
72.181887654,1334.0
72.260669349,1260.0
72.339451044,1194.0
72.418232740,1225.0
72.497014435,1262.0
72.575796130,1419.0
72.654577825,1528.0
72.733359520,1339.0
72.812141215,1384.0
72.890922910,1353.0
72.969704605,1264.0
73.048486300,1214.0
73.127267995,1273.0
73.206049690,1153.0
73.284831385,1238.0
73.363613080,1242.0
73.442394775,1314.0
73.521176470,1259.0
73.599958165,1173.0
73.678739860,1219.0
73.757521555,1264.0
73.836303250,1305.0
73.915084945,1208.0
73.993866640,1272.0
74.072648335,1265.0
74.151430030,1255.0
74.230211725,1191.0
74.308993420,1271.0
74.387775115,1152.0
74.466556810,1248.0
74.545338505,1245.0
74.624120200,1214.0
74.702901895,1247.0
74.781683590,1240.0
74.860465285,1239.0
74.939246980,1299.0
75.018028675,1303.0
75.096810370,1278.0
75.175592065,1261.0
75.254373760,1263.0
75.333155455,1220.0
75.411937150,1230.0
75.490718845,1155.0
75.569500540,1278.0
75.648282236,1241.0
75.727063931,1298.0
75.805845626,1311.0
75.884627321,1189.0
75.963409016,1245.0
76.042190711,1173.0
76.120972406,1278.0
76.199754101,1280.0
76.278535796,1239.0
76.357317491,1333.0
76.436099186,1245.0
76.514880881,1225.0
76.593662576,1263.0
76.672444271,1260.0
76.751225966,1274.0
76.830007661,1316.0
76.908789356,1289.0
76.987571051,1399.0
77.066352746,1640.0
77.145134441,2268.0
77.223916136,4331.0
77.302697831,3372.0
77.381479526,2356.0
77.460261221,3013.0
77.539042916,2195.0
77.617824611,1560.0
77.696606306,1429.0
77.775388001,1346.0
77.854169696,1293.0
77.932951391,1339.0
78.011733086,1256.0
78.090514781,1239.0
78.169296476,1250.0
78.248078171,1280.0
78.326859866,1258.0
78.405641561,1300.0
78.484423256,1201.0
78.563204951,1276.0
78.641986646,1217.0
78.720768341,1240.0
78.799550037,1257.0
78.878331732,1258.0
78.957113427,1193.0
79.035895122,1264.0
79.114676817,1212.0
79.193458512,1197.0
79.272240207,1278.0
79.351021902,1236.0
79.429803597,1226.0
79.508585292,1240.0
79.587366987,1266.0
79.666148682,1215.0
79.744930377,1216.0
79.823712072,1209.0
79.902493767,1303.0
79.981275462,1195.0
80.060057157,1162.0
80.138838852,1209.0
80.217620547,1275.0
80.296402242,1246.0
80.375183937,1219.0
80.453965632,1322.0
80.532747327,1219.0
80.611529022,1295.0
80.690310717,1197.0
80.769092412,1249.0
80.847874107,1181.0
80.926655802,1268.0
81.005437497,1300.0
81.084219192,1171.0
81.163000887,1210.0
81.241782582,1284.0
81.320564277,1179.0
81.399345972,1247.0
81.478127667,1277.0
81.556909362,1267.0
81.635691057,1385.0
81.714472752,1816.0
81.793254447,2244.0
81.872036142,1665.0
81.950817837,1646.0
82.029599533,1860.0
82.108381228,1564.0
82.187162923,1247.0
82.265944618,1293.0
82.344726313,1184.0
82.423508008,1285.0
82.502289703,1146.0
82.581071398,1296.0
82.659853093,1225.0
82.738634788,1254.0
82.817416483,1209.0
82.896198178,1256.0
82.974979873,1219.0
83.053761568,1243.0
83.132543263,1233.0
83.211324958,1208.0
83.290106653,1238.0
83.368888348,1192.0
83.447670043,1210.0
83.526451738,1301.0
83.605233433,1228.0
83.684015128,1188.0
83.762796823,1199.0
83.841578518,1251.0
83.920360213,1254.0
83.999141908,1212.0
84.077923603,1231.0
84.156705298,1239.0
84.235486993,1207.0
84.314268688,1270.0
84.393050383,1251.0
84.471832078,1303.0
84.550613773,1201.0
84.629395468,1305.0
84.708177163,1246.0
84.786958858,1275.0
84.865740553,1315.0
84.944522248,1176.0
85.023303943,1243.0
85.102085638,1226.0
85.180867333,1249.0
85.259649029,1188.0
85.338430724,1217.0
85.417212419,1225.0
85.495994114,1257.0
85.574775809,1175.0
85.653557504,1247.0
85.732339199,1298.0
85.811120894,1287.0
85.889902589,1231.0
85.968684284,1326.0
86.047465979,1320.0
86.126247674,1593.0
86.205029369,2142.0
86.283811064,2538.0
86.362592759,1784.0
86.441374454,1690.0
86.520156149,1957.0
86.598937844,1620.0
86.677719539,1326.0
86.756501234,1309.0
86.835282929,1171.0
86.914064624,1240.0
86.992846319,1214.0
87.071628014,1239.0
87.150409709,1209.0
87.229191404,1202.0
87.307973099,1224.0
87.386754794,1169.0
87.465536489,1158.0
87.544318184,1275.0
87.623099879,1277.0
87.701881574,1262.0
87.780663269,1199.0
87.859444964,1161.0
87.938226659,1196.0
88.017008354,1239.0
88.095790049,1209.0
88.174571744,1258.0
88.253353439,1204.0
88.332135134,1232.0
88.410916830,1179.0
88.489698525,1142.0
88.568480220,1263.0
88.647261915,1247.0
88.726043610,1199.0
88.804825305,1179.0
88.883607000,1197.0
88.962388695,1162.0
89.041170390,1276.0
89.119952085,1228.0
89.198733780,1211.0
89.277515475,1215.0
89.356297170,1228.0
89.435078865,1280.0
89.513860560,1165.0
89.592642255,1205.0
89.671423950,1232.0
89.750205645,1115.0
89.828987340,1186.0
89.907769035,1247.0
89.986550730,1216.0